2024-07-10 22:19:37,548 ERROR: Exception on /dietas [POST] [in /usr/local/lib/python3.10/site-packages/flask/app.py:1414]
Traceback (most recent call last):
  File "/usr/local/lib/python3.10/site-packages/sqlalchemy/engine/base.py", line 1965, in _exec_single_context
    self.dialect.do_execute(
  File "/usr/local/lib/python3.10/site-packages/sqlalchemy/engine/default.py", line 921, in do_execute
    cursor.execute(statement, parameters)
  File "/usr/local/lib/python3.10/site-packages/pymysql/cursors.py", line 148, in execute
    result = self._query(query)
  File "/usr/local/lib/python3.10/site-packages/pymysql/cursors.py", line 310, in _query
    conn.query(q)
  File "/usr/local/lib/python3.10/site-packages/pymysql/connections.py", line 548, in query
    self._affected_rows = self._read_query_result(unbuffered=unbuffered)
  File "/usr/local/lib/python3.10/site-packages/pymysql/connections.py", line 775, in _read_query_result
    result.read()
  File "/usr/local/lib/python3.10/site-packages/pymysql/connections.py", line 1156, in read
    first_packet = self.connection._read_packet()
  File "/usr/local/lib/python3.10/site-packages/pymysql/connections.py", line 725, in _read_packet
    packet.raise_for_error()
  File "/usr/local/lib/python3.10/site-packages/pymysql/protocol.py", line 221, in raise_for_error
    err.raise_mysql_exception(self._data)
  File "/usr/local/lib/python3.10/site-packages/pymysql/err.py", line 143, in raise_mysql_exception
    raise errorclass(errno, errval)
pymysql.err.IntegrityError: (1062, "Duplicate entry 'V5nmLXsJlJRC5lvs53TxOnFPvPv1' for key 'dietas.firebase_uuid'")

The above exception was the direct cause of the following exception:

Traceback (most recent call last):
  File "/usr/local/lib/python3.10/site-packages/flask/app.py", line 2190, in wsgi_app
    response = self.full_dispatch_request()
  File "/usr/local/lib/python3.10/site-packages/flask/app.py", line 1486, in full_dispatch_request
    rv = self.handle_user_exception(e)
  File "/usr/local/lib/python3.10/site-packages/flask_cors/extension.py", line 176, in wrapped_function
    return cors_after_request(app.make_response(f(*args, **kwargs)))
  File "/usr/local/lib/python3.10/site-packages/flask/app.py", line 1484, in full_dispatch_request
    rv = self.dispatch_request()
  File "/usr/local/lib/python3.10/site-packages/flask/app.py", line 1469, in dispatch_request
    return self.ensure_sync(self.view_functions[rule.endpoint])(**view_args)
  File "/app/app.py", line 35, in create_dieta
    session.commit()
  File "/usr/local/lib/python3.10/site-packages/sqlalchemy/orm/session.py", line 1920, in commit
    trans.commit(_to_root=True)
  File "<string>", line 2, in commit
  File "/usr/local/lib/python3.10/site-packages/sqlalchemy/orm/state_changes.py", line 139, in _go
    ret_value = fn(self, *arg, **kw)
  File "/usr/local/lib/python3.10/site-packages/sqlalchemy/orm/session.py", line 1236, in commit
    self._prepare_impl()
  File "<string>", line 2, in _prepare_impl
  File "/usr/local/lib/python3.10/site-packages/sqlalchemy/orm/state_changes.py", line 139, in _go
    ret_value = fn(self, *arg, **kw)
  File "/usr/local/lib/python3.10/site-packages/sqlalchemy/orm/session.py", line 1211, in _prepare_impl
    self.session.flush()
  File "/usr/local/lib/python3.10/site-packages/sqlalchemy/orm/session.py", line 4163, in flush
    self._flush(objects)
  File "/usr/local/lib/python3.10/site-packages/sqlalchemy/orm/session.py", line 4298, in _flush
    with util.safe_reraise():
  File "/usr/local/lib/python3.10/site-packages/sqlalchemy/util/langhelpers.py", line 147, in __exit__
    raise exc_value.with_traceback(exc_tb)
  File "/usr/local/lib/python3.10/site-packages/sqlalchemy/orm/session.py", line 4259, in _flush
    flush_context.execute()
  File "/usr/local/lib/python3.10/site-packages/sqlalchemy/orm/unitofwork.py", line 466, in execute
    rec.execute(self)
  File "/usr/local/lib/python3.10/site-packages/sqlalchemy/orm/unitofwork.py", line 642, in execute
    util.preloaded.orm_persistence.save_obj(
  File "/usr/local/lib/python3.10/site-packages/sqlalchemy/orm/persistence.py", line 93, in save_obj
    _emit_insert_statements(
  File "/usr/local/lib/python3.10/site-packages/sqlalchemy/orm/persistence.py", line 1226, in _emit_insert_statements
    result = connection.execute(
  File "/usr/local/lib/python3.10/site-packages/sqlalchemy/engine/base.py", line 1412, in execute
    return meth(
  File "/usr/local/lib/python3.10/site-packages/sqlalchemy/sql/elements.py", line 483, in _execute_on_connection
    return connection._execute_clauseelement(
  File "/usr/local/lib/python3.10/site-packages/sqlalchemy/engine/base.py", line 1635, in _execute_clauseelement
    ret = self._execute_context(
  File "/usr/local/lib/python3.10/site-packages/sqlalchemy/engine/base.py", line 1844, in _execute_context
    return self._exec_single_context(
  File "/usr/local/lib/python3.10/site-packages/sqlalchemy/engine/base.py", line 1984, in _exec_single_context
    self._handle_dbapi_exception(
  File "/usr/local/lib/python3.10/site-packages/sqlalchemy/engine/base.py", line 2339, in _handle_dbapi_exception
    raise sqlalchemy_exception.with_traceback(exc_info[2]) from e
  File "/usr/local/lib/python3.10/site-packages/sqlalchemy/engine/base.py", line 1965, in _exec_single_context
    self.dialect.do_execute(
  File "/usr/local/lib/python3.10/site-packages/sqlalchemy/engine/default.py", line 921, in do_execute
    cursor.execute(statement, parameters)
  File "/usr/local/lib/python3.10/site-packages/pymysql/cursors.py", line 148, in execute
    result = self._query(query)
  File "/usr/local/lib/python3.10/site-packages/pymysql/cursors.py", line 310, in _query
    conn.query(q)
  File "/usr/local/lib/python3.10/site-packages/pymysql/connections.py", line 548, in query
    self._affected_rows = self._read_query_result(unbuffered=unbuffered)
  File "/usr/local/lib/python3.10/site-packages/pymysql/connections.py", line 775, in _read_query_result
    result.read()
  File "/usr/local/lib/python3.10/site-packages/pymysql/connections.py", line 1156, in read
    first_packet = self.connection._read_packet()
  File "/usr/local/lib/python3.10/site-packages/pymysql/connections.py", line 725, in _read_packet
    packet.raise_for_error()
  File "/usr/local/lib/python3.10/site-packages/pymysql/protocol.py", line 221, in raise_for_error
    err.raise_mysql_exception(self._data)
  File "/usr/local/lib/python3.10/site-packages/pymysql/err.py", line 143, in raise_mysql_exception
    raise errorclass(errno, errval)
sqlalchemy.exc.IntegrityError: (pymysql.err.IntegrityError) (1062, "Duplicate entry 'V5nmLXsJlJRC5lvs53TxOnFPvPv1' for key 'dietas.firebase_uuid'")
[SQL: INSERT INTO dietas (firebase_uuid) VALUES (%(firebase_uuid)s)]
[parameters: {'firebase_uuid': 'V5nmLXsJlJRC5lvs53TxOnFPvPv1'}]
(Background on this error at: https://sqlalche.me/e/20/gkpj)
2024-07-10 22:19:37,597 INFO: 172.21.0.1 - - [10/Jul/2024 22:19:37] "[35m[1mPOST /dietas HTTP/1.1[0m" 500 - [in /usr/local/lib/python3.10/site-packages/werkzeug/_internal.py:187]
2024-07-10 22:20:27,365 INFO: Listagem de dietas realizada [in /app/app.py:44]
2024-07-10 22:20:27,375 INFO: 172.21.0.1 - - [10/Jul/2024 22:20:27] "GET /dietas HTTP/1.1" 200 - [in /usr/local/lib/python3.10/site-packages/werkzeug/_internal.py:187]
2024-07-10 22:20:34,649 INFO: Listagem de dietas realizada [in /app/app.py:44]
2024-07-10 22:20:34,653 INFO: 172.21.0.1 - - [10/Jul/2024 22:20:34] "GET /dietas HTTP/1.1" 200 - [in /usr/local/lib/python3.10/site-packages/werkzeug/_internal.py:187]
2024-07-10 22:20:40,622 INFO: 172.21.0.1 - - [10/Jul/2024 22:20:40] "[33mGET / HTTP/1.1[0m" 404 - [in /usr/local/lib/python3.10/site-packages/werkzeug/_internal.py:187]
2024-07-10 22:22:55,702 INFO: 172.21.0.1 - - [10/Jul/2024 22:22:55] "[33mGET / HTTP/1.1[0m" 404 - [in /usr/local/lib/python3.10/site-packages/werkzeug/_internal.py:187]
2024-07-10 22:23:00,780 INFO: Listagem de dietas realizada [in /app/app.py:44]
2024-07-10 22:23:00,784 INFO: 172.21.0.1 - - [10/Jul/2024 22:23:00] "GET /dietas HTTP/1.1" 200 - [in /usr/local/lib/python3.10/site-packages/werkzeug/_internal.py:187]
2024-07-10 22:29:57,895 INFO: Logging setup complete [in /app/logs/log_config.py:25]
2024-07-10 22:29:57,989 INFO: [31m[1mWARNING: This is a development server. Do not use it in a production deployment. Use a production WSGI server instead.[0m
 * Running on all addresses (0.0.0.0)
 * Running on http://127.0.0.1:5001
 * Running on http://172.30.0.3:5001 [in /usr/local/lib/python3.10/site-packages/werkzeug/_internal.py:187]
2024-07-10 22:29:57,991 INFO: [33mPress CTRL+C to quit[0m [in /usr/local/lib/python3.10/site-packages/werkzeug/_internal.py:187]
2024-07-10 22:30:29,401 INFO: Dieta com ID 1 deletada com sucesso. [in /app/app.py:67]
2024-07-10 22:30:29,402 INFO: 172.30.0.1 - - [10/Jul/2024 22:30:29] "DELETE /dietas/1 HTTP/1.1" 200 - [in /usr/local/lib/python3.10/site-packages/werkzeug/_internal.py:187]
2024-07-10 22:40:10,700 INFO: 172.30.0.1 - - [10/Jul/2024 22:40:10] "OPTIONS /dietas HTTP/1.1" 200 - [in /usr/local/lib/python3.10/site-packages/werkzeug/_internal.py:187]
2024-07-10 22:40:10,873 INFO: Dieta criada com sucesso: {'id': 7, 'firebase_uuid': 'V5nmLXsJlJRC5lvs53TxOnFPvPv1', 'horarios_refeicoes': [], 'refeicoes': []} [in /app/app.py:39]
2024-07-10 22:40:10,878 INFO: 172.30.0.1 - - [10/Jul/2024 22:40:10] "POST /dietas HTTP/1.1" 200 - [in /usr/local/lib/python3.10/site-packages/werkzeug/_internal.py:187]
2024-07-10 22:40:16,166 INFO: 172.30.0.1 - - [10/Jul/2024 22:40:16] "OPTIONS /dietas HTTP/1.1" 200 - [in /usr/local/lib/python3.10/site-packages/werkzeug/_internal.py:187]
2024-07-10 22:40:16,198 ERROR: Erro de integridade ao criar dieta: (pymysql.err.IntegrityError) (1062, "Duplicate entry 'V5nmLXsJlJRC5lvs53TxOnFPvPv1' for key 'dietas.firebase_uuid'")
[SQL: INSERT INTO dietas (firebase_uuid) VALUES (%(firebase_uuid)s)]
[parameters: {'firebase_uuid': 'V5nmLXsJlJRC5lvs53TxOnFPvPv1'}]
(Background on this error at: https://sqlalche.me/e/20/gkpj) [in /app/app.py:42]
